Workbook

Sheet ⚙ Assumptions
A1: PROGRAMME ASSUMPTIONS & PARAMETERS
A3: COVERAGE TARGETS & PROGRAMME SCALE (by intervention)
A4: Code | B4: Intervention | C4: Target Population Description | D4: Eligible Population (persons) | E4: Target Coverage (%) | F4: Planned Units (deliveries) | G4: Cycles / Doses per Person | H4: Total Delivery Units | I4: Year
A5: mii | B5: Mass ITN campaigns | C5: All household members (1 ITN for every two people) | D5: 2817703 | E5: 1 | F5: =IFERROR(ROUNDUP(D5*E5/$F$12,0),"") -> 1565391 | G5: 1 | H5: =IFERROR(F5*G5,"") -> 1565391 | I5: 2025
A6: mii_routine | B6: Routine ITN distribution | C6: Pregnant women attending ANC + children U5 | D6: =IFERROR(ROUND(D5*$F$14,0),"") -> 232179 | E6: 1 | F6: =IFERROR(ROUNDUP(D6*E6,0),"") -> 232179 | G6: 1 | H6: =IFERROR(F6*G6,"") -> 232179 | I6: 2025
A7: irs | B7: Indoor Residual Spraying | C7: Targeted sprayable structures in the household, in spray areas | E7: 0.85 | G7: 1 | H7: =IFERROR(F7*G7,"") -> 0 | I7: 2025
A8: smc | B8: Seasonal Malaria Chemoprevention | C8: Children 3–59 months in target zones | D8: =IFERROR(ROUND($F$16*$F$17,0),"") -> 307316 | E8: 1 | F8: =IFERROR(ROUND(D8*E8,0),"") -> 307316 | G8: 4 | H8: =IFERROR(F8*G8,"") -> 1229264 | I8: 2025
A9: iptsc | B9: Intermittent Preventive Treatment in School-Aged Children | C9: School-aged children 5–15 yrs (school enrolment-based) | E9: 0.85 | G9: 3 | H9: =IFERROR(F9*G9,"") -> 0 | I9: 2025
A10: vax | B10: Malaria Vaccine (RTS,S / R21) | C10: Children 5–17 months (birth cohort) | E10: 0.85 | G10: 4 | H10: =IFERROR(F10*G10,"") -> 0 | I10: 2025
B12: ITN quantification ratio — persons per net (mass campaign): | F12: 1.8
B13: ℹ️ Mass ITN nets = (eligible × coverage) ÷ persons-per-net (WHO standard = 2; use 1.8 to add a procurement buffer). Routine ITN = 1 net per eligible ANC/EPI contact. Rounded up to whole nets.
B14: Routine ITN eligible population (% of projected population): | F14: 0.0824
B15: ℹ️ Mass ITN eligible = total projected population (all household members). Routine ITN eligible = projected population × the percentage above.
B16: SMC target-area population: | F16: 2051511
B17: Children 3–59 months (% of SMC target-area population): | F17: 0.1498
B18: ℹ️ SMC eligible children = target-area population × children 3–59m %. Planned units = eligible × coverage. Total delivery units = planned units × cycles/doses per person (4 monthly SMC cycles).
B20: Exchange Rate: USD | C20: 72.39 | D20: https://www.cbg.gm/

Sheet 🗂 Interventions
A1: MALARIA INTERVENTION REGISTER — 6 CORE INTERVENTIONS
A3: Code | B3: Intervention Name | C3: Category | D3: Delivery Channel | E3: Target Population | F3: Active | G3: Notes / Comments
A4: mii | B4: Mass ITN campaigns | C4: Vector Control | D4: Mass campaign | E4: All household members (1 ITN for every two people) | F4: Y
A5: mii_routine | B5: Routine ITN distribution | C5: Vector Control | D5: Routine health system | E5: Pregnant women & children U5 | F5: Y
A6: irs | B6: Indoor Residual Spraying | C6: Vector Control | D6: Mass campaign | E6: Targeted sprayable structures in the household, in spray areas | F6: Y
A7: smc | B7: Seasonal Malaria Chemoprevention | C7: Chemoprevention | D7: Community-based | E7: Children 3–59 months | F7: Y
A8: iptsc | B8: Intermittent Preventive Treatment in School-Aged Children | C8: Chemoprevention | D8: School-based | E8: School-aged children 5–15 years | F8: Y
A9: vax | B9: Malaria Vaccine (RTS,S / R21) | C9: Chemoprevention | D9: Routine health system | E9: Children 5–17 months | F9: Y
A11: INTERVENTION DESCRIPTIONS & IMPLEMENTATION NOTES
A12: mii | B12: Mass ITN campaigns | C12: Mass distribution of Long-Lasting Insecticidal Nets (LLINs) to all households. Typically conducted every 3 years. Key commodity: PBO or conventional LLIN.
A13: mii_routine | B13: Routine ITN distribution | C13: Year-round distribution of LLINs through ANC and EPI contacts. Ensures continuous access between mass campaigns.
A14: irs | B14: Indoor Residual Spraying | C14: Application of residual insecticide to interior walls of houses. Requires annual spraying. Key inputs: insecticide, spray equipment, trained operators.
A15: smc | B15: Seasonal Malaria Chemoprevention | C15: Monthly preventive treatment with SPAQ for children 3–59 months during high transmission season (typically 3–4 cycles). Highly effective in Sahel.
A16: iptsc | B16: Intermittent Preventive Treatment in School-Aged Children | C16: DP (dihydroartemisinin-piperaquine) given to school-aged children (5–15 years) in 2–3 rounds per year, delivered through schools. WHO-recommended since June 2022; shrinks the asymptomatic parasite reservoir and reduces malaria burden in this age group.
A17: vax | B17: Malaria Vaccine (RTS,S / R21) | C17: 4-dose schedule of RTS,S/AS01 (Mosquirix) or 3-dose R21/Matrix-M delivered through EPI. Reduces clinical malaria in children by ~36–75%.

Sheet 📂 Cost Categories
A1: COST CATEGORY DEFINITIONS
A3: Code | B3: Category Name | C3: Definition | D3: Examples for Malaria Interventions | E3: Cost Type | F3: Notes
A4: PROC | B4: Procurement | C4: Purchase price of malaria commodities, drugs, diagnostics and equipment | D4: LLIN purchase, SPAQ blister pack, RTS,S vaccine vials, insecticide, RDTs | E4: Variable (per unit)
A5: DIST | B5: Distribution / Logistics | C5: Transport, storage and cold-chain delivery of commodities from central to point of use | D5: Freight, warehouse fees, last-mile vehicle hire, cold-chain maintenance | E5: Variable or Fixed
A6: OPS | B6: Operational | C6: Labour and direct field costs for implementing the intervention | D6: Spray operator wages, CHW per diem, EPI nurse session time, fuel | E6: Variable (per HH/child/woman)
A7: SUPP | B7: Support / Capacity | C7: Indirect support enabling quality programme delivery | D7: Training, supervision, technical assistance, capacity building | E7: Fixed or Variable
A8: M&E | B8: Monitoring & Evaluation | C8: Data collection, surveys, HMIS review and programme oversight | D8: Coverage surveys, HMIS tools, supervision visits | E8: Fixed per period
A9: COM | B9: Communication / BCC | C9: Behaviour change communication and community mobilisation activities | D9: Radio spots, IEC materials, community mobilisers | E9: Fixed or Variable
A10: ADMIN | B10: Administration | C10: Programme management, administration, banking and overhead | D10: Staff salaries (admin), bank fees, audit | E10: Fixed
A11: OTHER | B11: Other | C11: Any costs not captured above | D11: Contingency, unforeseen costs | E11: Variable

Sheet 📊 Summary
A1: UNIT COST SUMMARY BY INTERVENTION & COST CATEGORY
A2: Auto-calculated from Unit Costs sheet. Set Year filter in C3. Blue = inputs. Black = formulas.
A3: Filter Year: | C3: 2025
A5: Code | B5: Intervention | C5: Procurement (USD) | D5: Distribution (USD) | E5: Operational (USD) | F5: Support (USD) | G5: M&E (USD) | H5: Other (USD) | I5: TOTAL (USD) | J5: Unit Cost (Total, USD)
A6: mii | B6: Mass ITN campaigns | C6: =SUMPRODUCT(('📝 Unit Costs'!$A$6:$A$489=A6)*('📝 Unit Costs'!$C$6:$C$489="PROC")*('📝 Unit Costs'!$E$6:$E$489=$C$3)*'📝 Unit Costs'!$K$6:$K$489) -> 0 | D6: =SUMPRODUCT(('📝 Unit Costs'!$A$6:$A$489=A6)*('📝 Unit Costs'!$C$6:$C$489="DIST")*('📝 Unit Costs'!$E$6:$E$489=$C$3)*'📝 Unit Costs'!$K$6:$K$489) -> 0 | E6: =SUMPRODUCT(('📝 Unit Costs'!$A$6:$A$489=A6)*('📝 Unit Costs'!$C$6:$C$489="OPS")*('📝 Unit Costs'!$E$6:$E$489=$C$3)*'📝 Unit Costs'!$K$6:$K$489) -> 0 | F6: =SUMPRODUCT(('📝 Unit Costs'!$A$6:$A$489=A6)*('📝 Unit Costs'!$C$6:$C$489="SUPP")*('📝 Unit Costs'!$E$6:$E$489=$C$3)*'📝 Unit Costs'!$K$6:$K$489) -> 0 | G6: =SUMPRODUCT(('📝 Unit Costs'!$A$6:$A$489=A6)*('📝 Unit Costs'!$C$6:$C$489="M&E")*('📝 Unit Costs'!$E$6:$E$489=$C$3)*'📝 Unit Costs'!$K$6:$K$489) -> 0 | H6: =SUMPRODUCT(('📝 Unit Costs'!$A$6:$A$489=A6)*('📝 Unit Costs'!$C$6:$C$489="OTHER")*('📝 Unit Costs'!$E$6:$E$489=$C$3)*'📝 Unit Costs'!$K$6:$K$489) -> 0 | I6: =SUM(C6:H6) -> 0 | J6: =SUMPRODUCT(('📝 Unit Costs'!$A$6:$A$489=A6)*('📝 Unit Costs'!$E$6:$E$489=$C$3)*'📝 Unit Costs'!$G$6:$G$489) -> 7.94
A7: mii_routine | B7: Routine ITN distribution | C7: =SUMPRODUCT(('📝 Unit Costs'!$A$6:$A$489=A7)*('📝 Unit Costs'!$C$6:$C$489="PROC")*('📝 Unit Costs'!$E$6:$E$489=$C$3)*'📝 Unit Costs'!$K$6:$K$489) -> 0 | D7: =SUMPRODUCT(('📝 Unit Costs'!$A$6:$A$489=A7)*('📝 Unit Costs'!$C$6:$C$489="DIST")*('📝 Unit Costs'!$E$6:$E$489=$C$3)*'📝 Unit Costs'!$K$6:$K$489) -> 0 | E7: =SUMPRODUCT(('📝 Unit Costs'!$A$6:$A$489=A7)*('📝 Unit Costs'!$C$6:$C$489="OPS")*('📝 Unit Costs'!$E$6:$E$489=$C$3)*'📝 Unit Costs'!$K$6:$K$489) -> 0 | F7: =SUMPRODUCT(('📝 Unit Costs'!$A$6:$A$489=A7)*('📝 Unit Costs'!$C$6:$C$489="SUPP")*('📝 Unit Costs'!$E$6:$E$489=$C$3)*'📝 Unit Costs'!$K$6:$K$489) -> 0 | G7: =SUMPRODUCT(('📝 Unit Costs'!$A$6:$A$489=A7)*('📝 Unit Costs'!$C$6:$C$489="M&E")*('📝 Unit Costs'!$E$6:$E$489=$C$3)*'📝 Unit Costs'!$K$6:$K$489) -> 0 | H7: =SUMPRODUCT(('📝 Unit Costs'!$A$6:$A$489=A7)*('📝 Unit Costs'!$C$6:$C$489="OTHER")*('📝 Unit Costs'!$E$6:$E$489=$C$3)*'📝 Unit Costs'!$K$6:$K$489) -> 0 | I7: =SUM(C7:H7) -> 0 | J7: =SUMPRODUCT(('📝 Unit Costs'!$A$6:$A$489=A7)*('📝 Unit Costs'!$E$6:$E$489=$C$3)*'📝 Unit Costs'!$G$6:$G$489) -> 4.89
A8: irs | B8: Indoor Residual Spraying | C8: =SUMPRODUCT(('📝 Unit Costs'!$A$6:$A$489=A8)*('📝 Unit Costs'!$C$6:$C$489="PROC")*('📝 Unit Costs'!$E$6:$E$489=$C$3)*'📝 Unit Costs'!$K$6:$K$489) -> 0 | D8: =SUMPRODUCT(('📝 Unit Costs'!$A$6:$A$489=A8)*('📝 Unit Costs'!$C$6:$C$489="DIST")*('📝 Unit Costs'!$E$6:$E$489=$C$3)*'📝 Unit Costs'!$K$6:$K$489) -> 0 | E8: =SUMPRODUCT(('📝 Unit Costs'!$A$6:$A$489=A8)*('📝 Unit Costs'!$C$6:$C$489="OPS")*('📝 Unit Costs'!$E$6:$E$489=$C$3)*'📝 Unit Costs'!$K$6:$K$489) -> 0 | F8: =SUMPRODUCT(('📝 Unit Costs'!$A$6:$A$489=A8)*('📝 Unit Costs'!$C$6:$C$489="SUPP")*('📝 Unit Costs'!$E$6:$E$489=$C$3)*'📝 Unit Costs'!$K$6:$K$489) -> 0 | G8: =SUMPRODUCT(('📝 Unit Costs'!$A$6:$A$489=A8)*('📝 Unit Costs'!$C$6:$C$489="M&E")*('📝 Unit Costs'!$E$6:$E$489=$C$3)*'📝 Unit Costs'!$K$6:$K$489) -> 0 | H8: =SUMPRODUCT(('📝 Unit Costs'!$A$6:$A$489=A8)*('📝 Unit Costs'!$C$6:$C$489="OTHER")*('📝 Unit Costs'!$E$6:$E$489=$C$3)*'📝 Unit Costs'!$K$6:$K$489) -> 0 | I8: =SUM(C8:H8) -> 0 | J8: =SUMPRODUCT(('📝 Unit Costs'!$A$6:$A$489=A8)*('📝 Unit Costs'!$E$6:$E$489=$C$3)*'📝 Unit Costs'!$G$6:$G$489) -> 23.03
A9: smc | B9: Seasonal Malaria Chemoprevention | C9: =SUMPRODUCT(('📝 Unit Costs'!$A$6:$A$489=A9)*('📝 Unit Costs'!$C$6:$C$489="PROC")*('📝 Unit Costs'!$E$6:$E$489=$C$3)*'📝 Unit Costs'!$K$6:$K$489) -> 0 | D9: =SUMPRODUCT(('📝 Unit Costs'!$A$6:$A$489=A9)*('📝 Unit Costs'!$C$6:$C$489="DIST")*('📝 Unit Costs'!$E$6:$E$489=$C$3)*'📝 Unit Costs'!$K$6:$K$489) -> 0 | E9: =SUMPRODUCT(('📝 Unit Costs'!$A$6:$A$489=A9)*('📝 Unit Costs'!$C$6:$C$489="OPS")*('📝 Unit Costs'!$E$6:$E$489=$C$3)*'📝 Unit Costs'!$K$6:$K$489) -> 0 | F9: =SUMPRODUCT(('📝 Unit Costs'!$A$6:$A$489=A9)*('📝 Unit Costs'!$C$6:$C$489="SUPP")*('📝 Unit Costs'!$E$6:$E$489=$C$3)*'📝 Unit Costs'!$K$6:$K$489) -> 0 | G9: =SUMPRODUCT(('📝 Unit Costs'!$A$6:$A$489=A9)*('📝 Unit Costs'!$C$6:$C$489="M&E")*('📝 Unit Costs'!$E$6:$E$489=$C$3)*'📝 Unit Costs'!$K$6:$K$489) -> 0 | H9: =SUMPRODUCT(('📝 Unit Costs'!$A$6:$A$489=A9)*('📝 Unit Costs'!$C$6:$C$489="OTHER")*('📝 Unit Costs'!$E$6:$E$489=$C$3)*'📝 Unit Costs'!$K$6:$K$489) -> 0 | I9: =SUM(C9:H9) -> 0 | J9: =SUMPRODUCT(('📝 Unit Costs'!$A$6:$A$489=A9)*('📝 Unit Costs'!$E$6:$E$489=$C$3)*'📝 Unit Costs'!$G$6:$G$489) -> 1.81
A10: iptsc | B10: Intermittent Preventive Treatment in School-Aged Children | C10: =SUMPRODUCT(('📝 Unit Costs'!$A$6:$A$489=A10)*('📝 Unit Costs'!$C$6:$C$489="PROC")*('📝 Unit Costs'!$E$6:$E$489=$C$3)*'📝 Unit Costs'!$K$6:$K$489) -> 0 | D10: =SUMPRODUCT(('📝 Unit Costs'!$A$6:$A$489=A10)*('📝 Unit Costs'!$C$6:$C$489="DIST")*('📝 Unit Costs'!$E$6:$E$489=$C$3)*'📝 Unit Costs'!$K$6:$K$489) -> 0 | E10: =SUMPRODUCT(('📝 Unit Costs'!$A$6:$A$489=A10)*('📝 Unit Costs'!$C$6:$C$489="OPS")*('📝 Unit Costs'!$E$6:$E$489=$C$3)*'📝 Unit Costs'!$K$6:$K$489) -> 0 | F10: =SUMPRODUCT(('📝 Unit Costs'!$A$6:$A$489=A10)*('📝 Unit Costs'!$C$6:$C$489="SUPP")*('📝 Unit Costs'!$E$6:$E$489=$C$3)*'📝 Unit Costs'!$K$6:$K$489) -> 0 | G10: =SUMPRODUCT(('📝 Unit Costs'!$A$6:$A$489=A10)*('📝 Unit Costs'!$C$6:$C$489="M&E")*('📝 Unit Costs'!$E$6:$E$489=$C$3)*'📝 Unit Costs'!$K$6:$K$489) -> 0 | H10: =SUMPRODUCT(('📝 Unit Costs'!$A$6:$A$489=A10)*('📝 Unit Costs'!$C$6:$C$489="OTHER")*('📝 Unit Costs'!$E$6:$E$489=$C$3)*'📝 Unit Costs'!$K$6:$K$489) -> 0 | I10: =SUM(C10:H10) -> 0 | J10: =SUMPRODUCT(('📝 Unit Costs'!$A$6:$A$489=A10)*('📝 Unit Costs'!$E$6:$E$489=$C$3)*'📝 Unit Costs'!$G$6:$G$489) -> 3.2
A11: vax | B11: Malaria Vaccine (RTS,S / R21) | C11: =SUMPRODUCT(('📝 Unit Costs'!$A$6:$A$489=A11)*('📝 Unit Costs'!$C$6:$C$489="PROC")*('📝 Unit Costs'!$E$6:$E$489=$C$3)*'📝 Unit Costs'!$K$6:$K$489) -> 0 | D11: =SUMPRODUCT(('📝 Unit Costs'!$A$6:$A$489=A11)*('📝 Unit Costs'!$C$6:$C$489="DIST")*('📝 Unit Costs'!$E$6:$E$489=$C$3)*'📝 Unit Costs'!$K$6:$K$489) -> 0 | E11: =SUMPRODUCT(('📝 Unit Costs'!$A$6:$A$489=A11)*('📝 Unit Costs'!$C$6:$C$489="OPS")*('📝 Unit Costs'!$E$6:$E$489=$C$3)*'📝 Unit Costs'!$K$6:$K$489) -> 0 | F11: =SUMPRODUCT(('📝 Unit Costs'!$A$6:$A$489=A11)*('📝 Unit Costs'!$C$6:$C$489="SUPP")*('📝 Unit Costs'!$E$6:$E$489=$C$3)*'📝 Unit Costs'!$K$6:$K$489) -> 0 | G11: =SUMPRODUCT(('📝 Unit Costs'!$A$6:$A$489=A11)*('📝 Unit Costs'!$C$6:$C$489="M&E")*('📝 Unit Costs'!$E$6:$E$489=$C$3)*'📝 Unit Costs'!$K$6:$K$489) -> 0 | H11: =SUMPRODUCT(('📝 Unit Costs'!$A$6:$A$489=A11)*('📝 Unit Costs'!$C$6:$C$489="OTHER")*('📝 Unit Costs'!$E$6:$E$489=$C$3)*'📝 Unit Costs'!$K$6:$K$489) -> 0 | I11: =SUM(C11:H11) -> 0 | J11: =SUMPRODUCT(('📝 Unit Costs'!$A$6:$A$489=A11)*('📝 Unit Costs'!$E$6:$E$489=$C$3)*'📝 Unit Costs'!$G$6:$G$489) -> 9.5
A12: GRAND TOTAL | C12: =SUM(C6:C11) -> 0 | D12: =SUM(D6:D11) -> 0 | E12: =SUM(E6:E11) -> 0 | F12: =SUM(F6:F11) -> 0 | G12: =SUM(G6:G11) -> 0 | H12: =SUM(H6:H11) -> 0 | I12: =SUM(I6:I11) -> 0

Sheet 📝 Unit Costs
A1: UNIT COST DATA ENTRY — 6 CORE MALARIA INTERVENTIONS
A2: Blue cells = USER INPUTS | Black cells = AUTO-CALCULATED | Unit costs are entered directly in USD. Each row = one input line per intervention × cost category. Source documentation mandatory.
A3: IDENTIFICATION | F3: UNIT COST DETAILS | H3: SOURCE & NOTES | J3: SCALE-UP & TOTALS | M3: QUALITY
A4: Intervention Code | B4: Intervention Name | C4: Cost Category | D4: Input Description | E4: Year | F4: Unit of Measure | G4: Unit Cost (USD) | H4: Source / Reference | I4: Notes | J4: Target Units | K4: Total Cost (USD) | L4: % of Int. Total | M4: Data Quality Score (1–3)
A5: Code | B5: Auto-lookup | C5: PROC/DIST/OPS SUPP/M&E etc. | D5: Specific commodity or activity | E5: Ref. year | F5: per net / structure child / dose | G5: Enter cost in USD | H5: Study / report / programme data | I5: Optional context | J5: Planned delivery quantity | K5: unit cost × target units | L5: line ÷ intervention total | M5: 1=Model 2=Prog. 3=Primary study
A6: ▶ MASS ITN CAMPAIGNS [mii]
A7: mii | B7: =IFERROR(VLOOKUP(A7,'🗂 Interventions'!$A$4:$B$9,2,0),"") -> Mass ITN campaigns | C7: PROC | D7: Standard LLIN – pyrethroid-only, 180×160×150cm, bulk pkg | E7: 2025 | F7: Per net | G7: 1.72 | H7: GF PPM Ref. Price 2025 (FOB, bulk) | K7: =IFERROR(G7*J7,"") -> 0 | L7: =IFERROR(K7/SUMIF($A$6:$A$489,A7,$K$6:$K$489),"") | M7: 3
A8: mii | B8: =IFERROR(VLOOKUP(A8,'🗂 Interventions'!$A$4:$B$9,2,0),"") -> Mass ITN campaigns | C8: PROC | D8: PBO LLIN – pyrethroid-PBO, 180×160×150cm, bulk pkg | E8: 2025 | F8: Per net | G8: 1.92 | H8: GF PPM Ref. Price 2025 (FOB, bulk) | K8: =IFERROR(G8*J8,"") -> 0 | L8: =IFERROR(K8/SUMIF($A$6:$A$489,A8,$K$6:$K$489),"") | M8: 3
A9: mii | B9: =IFERROR(VLOOKUP(A9,'🗂 Interventions'!$A$4:$B$9,2,0),"") -> Mass ITN campaigns | C9: PROC | D9: Dual AI LLIN – CFP (chlorfenapyr+pyrethroid), 180×160×150cm | E9: 2025 | F9: Per net | G9: 2.35 | H9: GF PPM Ref. Price 2025 (FOB, bulk) | K9: =IFERROR(G9*J9,"") -> 0 | L9: =IFERROR(K9/SUMIF($A$6:$A$489,A9,$K$6:$K$489),"") | M9: 3
A10: mii | B10: =IFERROR(VLOOKUP(A10,'🗂 Interventions'!$A$4:$B$9,2,0),"") -> Mass ITN campaigns | C10: PROC | D10: Hanging kit (6 hooks + 1.5m string, bulk) | E10: 2025 | F10: Per net | G10: 0.08 | H10: GF PPM incl. in standard kit – estimate | K10: =IFERROR(G10*J10,"") -> 0 | L10: =IFERROR(K10/SUMIF($A$6:$A$489,A10,$K$6:$K$489),"") | M10: 1
A11: mii | B11: =IFERROR(VLOOKUP(A11,'🗂 Interventions'!$A$4:$B$9,2,0),"") -> Mass ITN campaigns | C11: DIST | D11: International freight & insurance (FOB→CIF) | E11: 2025 | F11: Per net | G11: 0.2 | H11: GF PPM freight indicative cost 2025 | K11: =IFERROR(G11*J11,"") -> 0 | L11: =IFERROR(K11/SUMIF($A$6:$A$489,A11,$K$6:$K$489),"") | M11: 2
A12: mii | B12: =IFERROR(VLOOKUP(A12,'🗂 Interventions'!$A$4:$B$9,2,0),"") -> Mass ITN campaigns | C12: DIST | D12: In-country central warehousing & handling | E12: 2025 | F12: Per net | G12: 0.18 | H12: Programme logistics data – country average | K12: =IFERROR(G12*J12,"") -> 0 | L12: =IFERROR(K12/SUMIF($A$6:$A$489,A12,$K$6:$K$489),"") | M12: 2
A13: mii | B13: =IFERROR(VLOOKUP(A13,'🗂 Interventions'!$A$4:$B$9,2,0),"") -> Mass ITN campaigns | C13: DIST | D13: District-level transport & storage | E13: 2025 | F13: Per net | G13: 0.22 | H13: Programme logistics data – country average | K13: =IFERROR(G13*J13,"") -> 0 | L13: =IFERROR(K13/SUMIF($A$6:$A$489,A13,$K$6:$K$489),"") | M13: 2
A14: mii | B14: =IFERROR(VLOOKUP(A14,'🗂 Interventions'!$A$4:$B$9,2,0),"") -> Mass ITN campaigns | C14: DIST | D14: Last-mile transport (district → distribution point) | E14: 2025 | F14: Per net | G14: 0.35 | H14: PMI/GF programme costing evidence 2024 | K14: =IFERROR(G14*J14,"") -> 0 | L14: =IFERROR(K14/SUMIF($A$6:$A$489,A14,$K$6:$K$489),"") | M14: 2
A15: mii | B15: =IFERROR(VLOOKUP(A15,'🗂 Interventions'!$A$4:$B$9,2,0),"") -> Mass ITN campaigns | C15: OPS | D15: Community mobilisation & household sensitisation | E15: 2025 | F15: Per net | G15: 0.14 | H15: PMI programme costing review 2025 | K15: =IFERROR(G15*J15,"") -> 0 | L15: =IFERROR(K15/SUMIF($A$6:$A$489,A15,$K$6:$K$489),"") | M15: 2
A16: mii | B16: =IFERROR(VLOOKUP(A16,'🗂 Interventions'!$A$4:$B$9,2,0),"") -> Mass ITN campaigns | C16: OPS | D16: Distribution point set-up & registration management | E16: 2025 | F16: Per net | G16: 0.18 | H16: PMI programme costing review 2025 | K16: =IFERROR(G16*J16,"") -> 0 | L16: =IFERROR(K16/SUMIF($A$6:$A$489,A16,$K$6:$K$489),"") | M16: 2
A17: mii | B17: =IFERROR(VLOOKUP(A17,'🗂 Interventions'!$A$4:$B$9,2,0),"") -> Mass ITN campaigns | C17: OPS | D17: Distributor per diem & field transport | E17: 2025 | F17: Per net | G17: 0.24 | H17: Country programme admin data | K17: =IFERROR(G17*J17,"") -> 0 | L17: =IFERROR(K17/SUMIF($A$6:$A$489,A17,$K$6:$K$489),"") | M17: 2
A18: mii | B18: =IFERROR(VLOOKUP(A18,'🗂 Interventions'!$A$4:$B$9,2,0),"") -> Mass ITN campaigns | C18: OPS | D18: HMIS data entry & reporting | E18: 2025 | F18: Per net | G18: 0.07 | H18: Country programme admin data | K18: =IFERROR(G18*J18,"") -> 0 | L18: =IFERROR(K18/SUMIF($A$6:$A$489,A18,$K$6:$K$489),"") | M18: 2
... A22: mii | B22: =IFERROR(VLOOKUP(A22,'🗂 Interventions'!$A$4:$B$9,2,0),"") -> Mass ITN campaigns | C22: M&E | D22: Programme monitoring visits & reporting tools | E22: 2025 | F22: Per net | G22: 0.04 | H22: Programme admin data | K22: =IFERROR(G22*J22,"") -> 0 | L22: =IFERROR(K22/SUMIF($A$6:$A$489,A22,$K$6:$K$489),"") | M22: 2
A23: ▶ ROUTINE ITN DISTRIBUTION [mii_routine]
A24: mii_routine | B24: =IFERROR(VLOOKUP(A24,'🗂 Interventions'!$A$4:$B$9,2,0),"") -> Routine ITN distribution | C24: PROC | D24: Standard LLIN – pyrethroid-only, individual bag (ANC/EPI) | E24: 2025 | F24: Per net | G24: 1.87 | H24: GF PPM Ref. Price 2025 (FOB, indiv. bag) | K24: =IFERROR(G24*J24,"") -> 0 | L24: =IFERROR(K24/SUMIF($A$6:$A$489,A24,$K$6:$K$489),"") | M24: 3
A25: mii_routine | B25: =IFERROR(VLOOKUP(A25,'🗂 Interventions'!$A$4:$B$9,2,0),"") -> Routine ITN distribution | C25: PROC | D25: PBO LLIN – pyrethroid-PBO, individual bag (ANC/EPI) | E25: 2025 | F25: Per net | G25: 1.99 | H25: GF PPM Ref. Price 2025 (FOB, indiv. bag) | K25: =IFERROR(G25*J25,"") -> 0 | L25: =IFERROR(K25/SUMIF($A$6:$A$489,A25,$K$6:$K$489),"") | M25: 3
A26: mii_routine | B26: =IFERROR(VLOOKUP(A26,'🗂 Interventions'!$A$4:$B$9,2,0),"") -> Routine ITN distribution | C26: DIST | D26: International freight & insurance (FOB→CIF) | E26: 2025 | F26: Per net | G26: 0.2 | H26: GF PPM freight indicative cost 2025 | K26: =IFERROR(G26*J26,"") -> 0 | L26: =IFERROR(K26/SUMIF($A$6:$A$489,A26,$K$6:$K$489),"") | M26: 2
A27: mii_routine | B27: =IFERROR(VLOOKUP(A27,'🗂 Interventions'!$A$4:$B$9,2,0),"") -> Routine ITN distribution | C27: DIST | D27: Central-to-facility supply chain & storage | E27: 2025 | F27: Per net | G27: 0.28 | H27: Programme logistics data | K27: =IFERROR(G27*J27,"") -> 0 | L27: =IFERROR(K27/SUMIF($A$6:$A$489,A27,$K$6:$K$489),"") | M27: 2
A28: mii_routine | B28: =IFERROR(VLOOKUP(A28,'🗂 Interventions'!$A$4:$B$9,2,0),"") -> Routine ITN distribution | C28: DIST | D28: Facility-level storage & stock management | E28: 2025 | F28: Per net | G28: 0.07 | H28: Programme admin data | K28: =IFERROR(G28*J28,"") -> 0 | L28: =IFERROR(K28/SUMIF($A$6:$A$489,A28,$K$6:$K$489),"") | M28: 1
A29: mii_routine | B29: =IFERROR(VLOOKUP(A29,'🗂 Interventions'!$A$4:$B$9,2,0),"") -> Routine ITN distribution | C29: OPS | D29: ANC/EPI health worker time (costed share) | E29: 2025 | F29: Per net | G29: 0.18 | H29: Time-motion study evidence | K29: =IFERROR(G29*J29,"") -> 0 | L29: =IFERROR(K29/SUMIF($A$6:$A$489,A29,$K$6:$K$489),"") | M29: 2
A30: mii_routine | B30: =IFERROR(VLOOKUP(A30,'🗂 Interventions'!$A$4:$B$9,2,0),"") -> Routine ITN distribution | C30: OPS | D30: Register & recording at facility | E30: 2025 | F30: Per net | G30: 0.05 | H30: Programme admin data | K30: =IFERROR(G30*J30,"") -> 0 | L30: =IFERROR(K30/SUMIF($A$6:$A$489,A30,$K$6:$K$489),"") | M30: 2
A31: mii_routine | B31: =IFERROR(VLOOKUP(A31,'🗂 Interventions'!$A$4:$B$9,2,0),"") -> Routine ITN distribution | C31: SUPP | D31: Health worker training on routine LLIN protocols | E31: 2025 | F31: Per net | G31: 0.14 | H31: Country training cost data | K31: =IFERROR(G31*J31,"") -> 0 | L31: =IFERROR(K31/SUMIF($A$6:$A$489,A31,$K$6:$K$489),"") | M31: 2
A32: mii_routine | B32: =IFERROR(VLOOKUP(A32,'🗂 Interventions'!$A$4:$B$9,2,0),"") -> Routine ITN distribution | C32: SUPP | D32: Supervision of ANC/EPI distribution quality | E32: 2025 | F32: Per net | G32: 0.07 | H32: Supervision cost estimates | K32: =IFERROR(G32*J32,"") -> 0 | L32: =IFERROR(K32/SUMIF($A$6:$A$489,A32,$K$6:$K$489),"") | M32: 2
A33: mii_routine | B33: =IFERROR(VLOOKUP(A33,'🗂 Interventions'!$A$4:$B$9,2,0),"") -> Routine ITN distribution | C33: M&E | D33: Routine HMIS data reporting & validation | E33: 2025 | F33: Per net | G33: 0.04 | H33: Programme admin data | K33: =IFERROR(G33*J33,"") -> 0 | L33: =IFERROR(K33/SUMIF($A$6:$A$489,A33,$K$6:$K$489),"") | M33: 2
A34: ▶ INDOOR RESIDUAL SPRAYING [irs]
A35: irs | B35: =IFERROR(VLOOKUP(A35,'🗂 Interventions'!$A$4:$B$9,2,0),"") -> Indoor Residual Spraying | C35: PROC | D35: Insecticide – Actellic 300CS (pirimiphos-methyl, 300g/L SC) | E35: 2025 | F35: Per Structure | G35: 5.2 | H35: NgenIRS/IVCC programme pricing 2025; PMI costing data | K35: =IFERROR(G35*J35,"") -> 0 | L35: =IFERROR(K35/SUMIF($A$6:$A$489,A35,$K$6:$K$489),"") | M35: 2
A36: irs | B36: =IFERROR(VLOOKUP(A36,'🗂 Interventions'!$A$4:$B$9,2,0),"") -> Indoor Residual Spraying | C36: PROC | D36: Insecticide – SumiShield 50WG (clothianidin, single AI) | E36: 2025 | F36: Per Structure | G36: 6.5 | H36: NgenIRS/IVCC programme pricing 2025 | K36: =IFERROR(G36*J36,"") -> 0 | L36: =IFERROR(K36/SUMIF($A$6:$A$489,A36,$K$6:$K$489),"") | M36: 2
A37: irs | B37: =IFERROR(VLOOKUP(A37,'🗂 Interventions'!$A$4:$B$9,2,0),"") -> Indoor Residual Spraying | C37: PROC | D37: Insecticide – Fludora Fusion (clothianidin+deltamethrin WP) | E37: 2025 | F37: Per Structure | G37: 6.8 | H37: NgenIRS/IVCC programme pricing 2025 | K37: =IFERROR(G37*J37,"") -> 0 | L37: =IFERROR(K37/SUMIF($A$6:$A$489,A37,$K$6:$K$489),"") | M37: 2
A38: irs | B38: =IFERROR(VLOOKUP(A38,'🗂 Interventions'!$A$4:$B$9,2,0),"") -> Indoor Residual Spraying | C38: PROC | D38: Spray pump amortisation (knapsack/motorised) | E38: 2025 | F38: Per Structure | G38: 0.38 | H38: Equipment cost models; PMI 2024 | K38: =IFERROR(G38*J38,"") -> 0 | L38: =IFERROR(K38/SUMIF($A$6:$A$489,A38,$K$6:$K$489),"") | M38: 2
A39: irs | B39: =IFERROR(VLOOKUP(A39,'🗂 Interventions'!$A$4:$B$9,2,0),"") -> Indoor Residual Spraying | C39: PROC | D39: PPE per operator (gloves, mask, overalls, boot covers) | E39: 2025 | F39: Per Structure | G39: 0.28 | H39: Supply chain data 2025 | K39: =IFERROR(G39*J39,"") -> 0 | L39: =IFERROR(K39/SUMIF($A$6:$A$489,A39,$K$6:$K$489),"") | M39: 2
A40: irs | B40: =IFERROR(VLOOKUP(A40,'🗂 Interventions'!$A$4:$B$9,2,0),"") -> Indoor Residual Spraying | C40: DIST | D40: Insecticide & equipment freight to district stores | E40: 2025 | F40: Per Structure | G40: 0.32 | H40: Programme logistics data | K40: =IFERROR(G40*J40,"") -> 0 | L40: =IFERROR(K40/SUMIF($A$6:$A$489,A40,$K$6:$K$489),"") | M40: 2
A41: irs | B41: =IFERROR(VLOOKUP(A41,'🗂 Interventions'!$A$4:$B$9,2,0),"") -> Indoor Residual Spraying | C41: DIST | D41: District-level storage & stock control | E41: 2025 | F41: Per Structure | G41: 0.1 | H41: Programme logistics estimate | K41: =IFERROR(G41*J41,"") -> 0 | L41: =IFERROR(K41/SUMIF($A$6:$A$489,A41,$K$6:$K$489),"") | M41: 1
A42: irs | B42: =IFERROR(VLOOKUP(A42,'🗂 Interventions'!$A$4:$B$9,2,0),"") -> Indoor Residual Spraying | C42: OPS | D42: Spray operator wages & per diem (per HH sprayed) | E42: 2025 | F42: Per Structure | G42: 2.4 | H42: Country HR records / PMI 2024 | K42: =IFERROR(G42*J42,"") -> 0 | L42: =IFERROR(K42/SUMIF($A$6:$A$489,A42,$K$6:$K$489),"") | M42: 2
A43: irs | B43: =IFERROR(VLOOKUP(A43,'🗂 Interventions'!$A$4:$B$9,2,0),"") -> Indoor Residual Spraying | C43: OPS | D43: Pump washing, decontamination & waste disposal | E43: 2025 | F43: Per Structure | G43: 0.18 | H43: Operational costing 2025 | K43: =IFERROR(G43*J43,"") -> 0 | L43: =IFERROR(K43/SUMIF($A$6:$A$489,A43,$K$6:$K$489),"") | M43: 2
...

Sheet 🏠 Dashboard
B2: COOP MALARIA ELIMINATION PROGRAMME Unit Cost Comprehensive Tool — v2.1
B6: Focused on 6 Core Interventions | Vector Control & Chemoprevention | Comprehensive Input-Level Costing
B9: Mass ITN Campaigns | D9: Routine ITN Distribution | F9: Indoor Residual Spraying | H9: Seasonal Malaria Chemoprev. | J9: IPT School- Aged Children | L9: Malaria Vaccine RTS,S / R21
B10: MII | D10: MII_ROUTINE | F10: IRS | H10: SMC | J10: IPTSC | L10: VAX
B13: Programme Information
B14: Country / Region:
B15: Programme Name: | C15: COOP Malaria Elimination
B16: Reporting Year: | C16: 2025
B17: Base Currency: | C17: USD
B18: Prepared By:
B19: Date:
B20: Version: | C20: 2.1
B22: ℹ️ WORKFLOW: ① Assumptions — set coverage targets & parameters → ② Unit Costs — enter/verify all cost lines → ③ Summary — review totals by intervention & category → ④ Cost-per-Person — compute cost-effectiveness metrics

Sheet 📉 Cost-per-Person
A1: COST-PER-PERSON PROTECTED / TREATED ANALYSIS
A2: Enter eligible population and coverage in the Assumptions sheet. Cost totals link from Summary sheet.
A4: Code | B4: Intervention | C4: Year | D4: Total Programme Cost (USD) | E4: Eligible Population (persons) | F4: Actual Coverage (%) | G4: Persons Reached | H4: Cost per Person Targeted (USD) | I4: Cost per Person Reached (USD)
A5: mii | B5: Mass ITN campaigns | C5: 2025 | D5: =IFERROR('📊 Summary'!I6,"") -> 0 | E5: =IFERROR('⚙ Assumptions'!D5,"") -> 2817703 | F5: =IFERROR('⚙ Assumptions'!E5,"") -> 1 | G5: =IFERROR(E5*F5,"") -> 2817703 | H5: =IFERROR(D5/E5,"") -> 0 | I5: =IFERROR(D5/G5,"") -> 0
A6: mii_routine | B6: Routine ITN distribution | C6: 2025 | D6: =IFERROR('📊 Summary'!I7,"") -> 0 | E6: =IFERROR('⚙ Assumptions'!D6,"") -> 232179 | F6: =IFERROR('⚙ Assumptions'!E6,"") -> 1 | G6: =IFERROR(E6*F6,"") -> 232179 | H6: =IFERROR(D6/E6,"") -> 0 | I6: =IFERROR(D6/G6,"") -> 0
A7: irs | B7: Indoor Residual Spraying | C7: 2025 | D7: =IFERROR('📊 Summary'!I8,"") -> 0 | E7: =IFERROR('⚙ Assumptions'!D7,"") -> 0 | F7: =IFERROR('⚙ Assumptions'!E7,"") -> 0.85 | G7: =IFERROR(E7*F7,"") -> 0 | H7: =IFERROR(D7/E7,"") | I7: =IFERROR(D7/G7,"")
A8: smc | B8: Seasonal Malaria Chemoprevention | C8: 2025 | D8: =IFERROR('📊 Summary'!I9,"") -> 0 | E8: =IFERROR('⚙ Assumptions'!D8,"") -> 307316 | F8: =IFERROR('⚙ Assumptions'!E8,"") -> 1 | G8: =IFERROR(E8*F8,"") -> 307316 | H8: =IFERROR(D8/E8,"") -> 0 | I8: =IFERROR(D8/G8,"") -> 0
A9: iptsc | B9: Intermittent Preventive Treatment in School-Aged Children | C9: 2025 | D9: =IFERROR('📊 Summary'!I10,"") -> 0 | E9: =IFERROR('⚙ Assumptions'!D9,"") -> 0 | F9: =IFERROR('⚙ Assumptions'!E9,"") -> 0.85 | G9: =IFERROR(E9*F9,"") -> 0 | H9: =IFERROR(D9/E9,"") | I9: =IFERROR(D9/G9,"")
A10: vax | B10: Malaria Vaccine (RTS,S / R21) | C10: 2025 | D10: =IFERROR('📊 Summary'!I11,"") -> 0 | E10: =IFERROR('⚙ Assumptions'!D10,"") -> 0 | F10: =IFERROR('⚙ Assumptions'!E10,"") -> 0.85 | G10: =IFERROR(E10*F10,"") -> 0 | H10: =IFERROR(D10/E10,"") | I10: =IFERROR(D10/G10,"")

Sheet ✅ Data Quality
A1: DATA QUALITY & SOURCE VALIDATION LOG
A2: Score: 1 = Modelled/estimated | 2 = Programme administrative data | 3 = Primary data / peer-reviewed study (highest)
A4: Intervention Code | B4: Input Description | C4: Data Source | D4: Reference Document / URL | E4: Date Retrieved | F4: Quality Score | G4: Notes/Caveats
A5: mii | B5: Standard LLIN (bulk) – $1.72/net FOB | C5: GF Pooled Procurement Mechanism | D5: GF PPM LLIN Ref. Price 2025 (psm_llinreferenceprices_table_en.pdf) | E5: 2025 | F5: 3 | G5: GF PPM framework agreement price; bulk pkg for mass campaigns
A6: mii | B6: PBO LLIN (bulk) – $1.92/net FOB | C6: GF Pooled Procurement Mechanism | D6: GF PPM LLIN Ref. Price 2025 | E6: 2025 | F6: 3 | G6: GF PPM framework agreement price
A7: mii | B7: Dual AI CFP LLIN (bulk) – $2.35/net FOB | C7: GF Pooled Procurement Mechanism | D7: GF PPM LLIN Ref. Price 2025 | E7: 2025 | F7: 3 | G7: Next-gen chlorfenapyr+pyrethroid net
A8: mii | B8: Distribution cost per net | C8: Programme admin data | D8: NMC Campaign Report 2025 | E8: 2025-06 | F8: 2 | G8: Based on 2024/25 campaign actuals; update with country data
A9: irs | B9: Actellic 300CS – ~$5.20/HH | C9: NgenIRS/IVCC & PMI programme data | D9: NgenIRS Programme Pricing 2025; Alonso et al. Malaria J 2021 | E9: 2025-03 | F9: 2 | G9: Derived: ~$18-22/bottle ÷ ~3.5 HH per bottle; update w/ country quote
A10: smc | B10: SPAQ (child ≤15kg) – $0.24/blister | C10: GF Pooled Procurement Mechanism | D10: GF PPM ACT Ref. Price 2025 (ppm_act-reference-pricing_table_en.pdf) | E10: 2025 | F10: 3 | G10: AQ76.5mg+SP12.5/250mg co-blister, pack50 = $11.91; per treatment = $0.24
A11: smc | B11: SPAQ (child >15kg) – $0.28/blister | C11: GF Pooled Procurement Mechanism | D11: GF PPM ACT Ref. Price 2025 | E11: 2025 | F11: 3 | G11: AQ153mg+SP25/500mg co-blister, pack50 = $14.00; per treatment = $0.28
A12: iptsc | B12: DP (DHA-PPQ) 40/320mg – $1.46/course | C12: GF Pooled Procurement Mechanism | D12: GF PPM ACT Ref. Price 2025 (ppm_act-reference-pricing_table_en.pdf) | E12: 2025 | F12: 3 | G12: DHA/PPQ 40/320mg tablet, blister of 9, pack of 25 = $36.38; per course = $1.46
A13: vax | B13: R21/Matrix-M – $3.90/dose (Gavi/UNICEF 2025) | C13: Gavi / UNICEF / Serum Institute | D13: Gavi-UNICEF pricing deal press release 24 Nov 2025 (gavi.org) | E13: 2025-11 | F13: 3 | G13: Gavi/UNICEF 2025 price; 4-dose course = $15.60/child
A14: vax | B14: RTS,S – ~$9.50/dose (reducing to <$5 progressively) | C14: GSK / Bharat Biotech | D14: Devex Nov 2025; RTS,S reduction announced Jun 2025 (GSK/Bharat Biotech) | E14: 2025-06 | F14: 3 | G14: 4-dose course ~$38/child at current price; progressive reduction to <$5/dose
A15: vax | B15: Cold-chain cost per child | C15: UNICEF EPI Assessment | D15: UNICEF Cold Chain Assessment 2024-25 | E15: 2025-04 | F15: 2 | G15: Country-specific; $1.15/child estimate – update with national EPI data

Sheet 🔍 Cost Breakdown
A1: UNIT COST COMPONENT BREAKDOWN BY INTERVENTION
A2: Reference unit costs per commodity/activity. Values drawn from Unit Costs sheet. Use this view to review cost drivers at a glance.
A4: Code | B4: Intervention | C4: Cost Category | D4: Input Description | E4: Unit | F4: Reference Unit Cost (USD) | G4: Source | H4: Notes
A5: ▶ MASS ITN CAMPAIGNS
A6: mii | B6: Mass ITN campaigns | C6: PROC | D6: Standard LLIN – pyrethroid-only, 180×160×150cm, bulk pkg | E6: Per net | F6: 1.72 | G6: GF PPM Ref. Price 2025 (FOB, bulk)
A7: mii | B7: Mass ITN campaigns | C7: PROC | D7: PBO LLIN – pyrethroid-PBO, 180×160×150cm, bulk pkg | E7: Per net | F7: 1.92 | G7: GF PPM Ref. Price 2025 (FOB, bulk)
A8: mii | B8: Mass ITN campaigns | C8: PROC | D8: Dual AI LLIN – CFP (chlorfenapyr+pyrethroid), 180×160×150cm | E8: Per net | F8: 2.35 | G8: GF PPM Ref. Price 2025 (FOB, bulk)
A9: mii | B9: Mass ITN campaigns | C9: PROC | D9: Hanging kit (6 hooks + 1.5m string, bulk) | E9: Per net | F9: 0.08 | G9: GF PPM incl. in standard kit – estimate
A10: mii | B10: Mass ITN campaigns | C10: DIST | D10: International freight & insurance (FOB→CIF) | E10: Per net | F10: 0.2 | G10: GF PPM freight indicative cost 2025
A11: mii | B11: Mass ITN campaigns | C11: DIST | D11: In-country central warehousing & handling | E11: Per net | F11: 0.18 | G11: Programme logistics data – country average
A12: mii | B12: Mass ITN campaigns | C12: DIST | D12: District-level transport & storage | E12: Per net | F12: 0.22 | G12: Programme logistics data – country average
A13: mii | B13: Mass ITN campaigns | C13: DIST | D13: Last-mile transport (district → distribution point) | E13: Per net | F13: 0.35 | G13: PMI/GF programme costing evidence 2024
A14: mii | B14: Mass ITN campaigns | C14: OPS | D14: Community mobilisation & household sensitisation | E14: Per net | F14: 0.14 | G14: PMI programme costing review 2025
A15: mii | B15: Mass ITN campaigns | C15: OPS | D15: Distribution point set-up & registration management | E15: Per net | F15: 0.18 | G15: PMI programme costing review 2025
A16: mii | B16: Mass ITN campaigns | C16: OPS | D16: Distributor per diem & field transport | E16: Per net | F16: 0.24 | G16: Country programme admin data
A17: mii | B17: Mass ITN campaigns | C17: OPS | D17: HMIS data entry & reporting | E17: Per net | F17: 0.07 | G17: Country programme admin data
... A21: mii | B21: Mass ITN campaigns | C21: M&E | D21: Programme monitoring visits & reporting tools | E21: Per net | F21: 0.04 | G21: Programme admin data
A22: ▶ ROUTINE ITN DISTRIBUTION
A23: mii_routine | B23: Routine ITN distribution | C23: PROC | D23: Standard LLIN – pyrethroid-only, individual bag (ANC/EPI) | E23: Per net | F23: 1.87 | G23: GF PPM Ref. Price 2025 (FOB, indiv. bag)
A24: mii_routine | B24: Routine ITN distribution | C24: PROC | D24: PBO LLIN – pyrethroid-PBO, individual bag (ANC/EPI) | E24: Per net | F24: 1.99 | G24: GF PPM Ref. Price 2025 (FOB, indiv. bag)
A25: mii_routine | B25: Routine ITN distribution | C25: DIST | D25: International freight & insurance (FOB→CIF) | E25: Per net | F25: 0.2 | G25: GF PPM freight indicative cost 2025
A26: mii_routine | B26: Routine ITN distribution | C26: DIST | D26: Central-to-facility supply chain & storage | E26: Per net | F26: 0.28 | G26: Programme logistics data
A27: mii_routine | B27: Routine ITN distribution | C27: DIST | D27: Facility-level storage & stock management | E27: Per net | F27: 0.07 | G27: Programme admin data
A28: mii_routine | B28: Routine ITN distribution | C28: OPS | D28: ANC/EPI health worker time (costed share) | E28: Per net | F28: 0.18 | G28: Time-motion study evidence
A29: mii_routine | B29: Routine ITN distribution | C29: OPS | D29: Register & recording at facility | E29: Per net | F29: 0.05 | G29: Programme admin data
A30: mii_routine | B30: Routine ITN distribution | C30: SUPP | D30: Health worker training on routine LLIN protocols | E30: Per net | F30: 0.14 | G30: Country training cost data
A31: mii_routine | B31: Routine ITN distribution | C31: SUPP | D31: Supervision of ANC/EPI distribution quality | E31: Per net | F31: 0.07 | G31: Supervision cost estimates
A32: mii_routine | B32: Routine ITN distribution | C32: M&E | D32: Routine HMIS data reporting & validation | E32: Per net | F32: 0.04 | G32: Programme admin data
A33: ▶ INDOOR RESIDUAL SPRAYING
A34: irs | B34: Indoor Residual Spraying | C34: PROC | D34: Insecticide – Actellic 300CS (pirimiphos-methyl, 300g/L SC) | E34: Per Structure | F34: 5.2 | G34: NgenIRS/IVCC programme pricing 2025; PMI costing data
A35: irs | B35: Indoor Residual Spraying | C35: PROC | D35: Insecticide – SumiShield 50WG (clothianidin, single AI) | E35: Per Structure | F35: 6.5 | G35: NgenIRS/IVCC programme pricing 2025
A36: irs | B36: Indoor Residual Spraying | C36: PROC | D36: Insecticide – Fludora Fusion (clothianidin+deltamethrin WP) | E36: Per Structure | F36: 6.8 | G36: NgenIRS/IVCC programme pricing 2025
A37: irs | B37: Indoor Residual Spraying | C37: PROC | D37: Spray pump amortisation (knapsack/motorised) | E37: Per Structure | F37: 0.38 | G37: Equipment cost models; PMI 2024
A38: irs | B38: Indoor Residual Spraying | C38: PROC | D38: PPE per operator (gloves, mask, overalls, boot covers) | E38: Per Structure | F38: 0.28 | G38: Supply chain data 2025
A39: irs | B39: Indoor Residual Spraying | C39: DIST | D39: Insecticide & equipment freight to district stores | E39: Per Structure | F39: 0.32 | G39: Programme logistics data
A40: irs | B40: Indoor Residual Spraying | C40: DIST | D40: District-level storage & stock control | E40: Per Structure | F40: 0.1 | G40: Programme logistics estimate
A41: irs | B41: Indoor Residual Spraying | C41: OPS | D41: Spray operator wages & per diem (per HH sprayed) | E41: Per Structure | F41: 2.4 | G41: Country HR records / PMI 2024
A42: irs | B42: Indoor Residual Spraying | C42: OPS | D42: Pump washing, decontamination & waste disposal | E42: Per Structure | F42: 0.18 | G42: Operational costing 2025
A43: irs | B43: Indoor Residual Spraying | C43: OPS | D43: Team leader & supervisor per diem (per HH) | E43: Per Structure | F43: 0.28 | G43: Country HR records / PMI 2024
A44: irs | B44: Indoor Residual Spraying | C44: OPS | D44: Community mobilisation & household registration | E44: Per Structure | F44: 0.14 | G44: PMI programme costing 2025
...

Sheet 📋 Instructions
A1: HOW TO USE THIS TOOL — STEP-BY-STEP GUIDE
A3: STEP 1: Set Programme Parameters
A4: • Open the ⚙ Assumptions sheet.
A5: • Enter the coverage targets: eligible population, target coverage (%), and cycles/doses per person for each intervention.
A6: • In the Coverage Targets table enter: eligible population, target coverage (%), and planned delivery units for each intervention.
A7: • Adjust the ITN persons-per-net ratio and SMC parameters as needed.
A9: STEP 2: Review Intervention List
A10: • Open 🗂 Interventions — all 6 core interventions are pre-loaded.
A11: • Review target population descriptions and delivery channels.
A12: • Add notes or adjust definitions to match your country context.
A14: STEP 3: Enter / Verify Unit Costs
A15: • Open 📝 Unit Costs — this is the main data entry sheet.
... A34: • A transparent quality log is required for all donor-facing submissions.
